Workbook

Sheet Collection DB
A1: Week # | B1: SBUX FY Week # | C1: FY Week # Helper | D1: Date | E1: Day of the week | F1: Store | G1: SCG mass lbs | H1: Net lbs | I1: # of Days between collections | J1: Days Since 1st Collection | K1: Who initiated pickup? | L1: Per Day (lbs) | M1: Running Total | N1: Master Gardener | O1: MG Deposit Date | P1: Cardboard (lbs) | Q1: Food Waste (lbs) | R1: Route | S1: Miles Driven | T1: Truck Odometer | U1: Notes
A2: =WEEKNUM(D2,1) -> 17 | B2: =WEEKNUM(C2,1) -> 30 | C2: =D2+92 -> 45132 | D2: 45040 | E2: =TEXT(D2,"dddd") -> Monday | F2: 100 East 10th Street | G2: 59.6 | H2: =G2-8 -> 51.6 | J2: 0 | K2: Scheduled | L2: =H2/1 -> 51.6 | M2: =SUM(H$2:H2) -> 51.6 | N2: 0 | P2: 0 | Q2: 0 | R2: Home to 100 East 10th Street | S2: =VLOOKUP(Table1[[#This Row],[Route]],'Dropdown Lists'!$M$2:$N$7,2,FALSE) -> 11.4
A3: =WEEKNUM(D3,1) -> 17 | B3: =WEEKNUM(C3,1) -> 30 | C3: =D3+92 -> 45135 | D3: 45043 | E3: =TEXT(D3,"dddd") -> Thursday | F3: 100 East 10th Street | G3: 97.1 | H3: =G3-8 -> 89.1 | I3: =IF(D3-D2<0, 0, D3-D2) -> 3 | J3: =D3-$D$2 -> 3 | K3: Store | L3: =H3/I3 -> 29.7 | M3: =SUM(H$2:H3) -> 140.7 | N3: 0 | P3: 0 | Q3: 0 | R3: Trinity to 100 East 10th Street | S3: =VLOOKUP(Table1[[#This Row],[Route]],'Dropdown Lists'!$M$2:$N$7,2,FALSE) -> 13.5
A4: =WEEKNUM(D4,1) -> 18 | B4: =WEEKNUM(C4,1) -> 31 | C4: =D4+92 -> 45142 | D4: 45050 | E4: =TEXT(D4,"dddd") -> Thursday | F4: 100 East 10th Street | G4: 141.3 | H4: =G4-8 -> 133.3 | I4: =IF(D4-D3<0, 0, D4-D3) -> 7 | J4: =D4-$D$2 -> 10 | K4: Store | L4: =H4/I4 -> 19.042857 | M4: =SUM(H$2:H4) -> 274 | N4: 0 | P4: 0 | Q4: 0 | R4: Trinity to 100 East 10th Street | S4: =VLOOKUP(Table1[[#This Row],[Route]],'Dropdown Lists'!$M$2:$N$7,2,FALSE) -> 13.5
A5: =WEEKNUM(D5,1) -> 18 | B5: =WEEKNUM(C5,1) -> 32 | C5: =D5+92 -> 45144 | D5: 45052 | E5: =TEXT(D5,"dddd") -> Saturday | F5: 100 East 10th Street | G5: 70.6 | H5: =G5-8 -> 62.6 | I5: =IF(D5-D4<0, 0, D5-D4) -> 2 | J5: =D5-$D$2 -> 12 | K5: Store | L5: =H5/I5 -> 31.3 | M5: =SUM(H$2:H5) -> 336.6 | N5: 0 | P5: 0 | Q5: 0 | R5: Home to 100 East 10th Street | S5: =VLOOKUP(Table1[[#This Row],[Route]],'Dropdown Lists'!$M$2:$N$7,2,FALSE) -> 11.4
A6: =WEEKNUM(D6,1) -> 19 | B6: =WEEKNUM(C6,1) -> 32 | C6: =D6+92 -> 45150 | D6: 45058 | E6: =TEXT(D6,"dddd") -> Friday | F6: 100 East 10th Street | G6: 136.4 | H6: =G6-8 -> 128.4 | I6: =IF(D6-D5<0, 0, D6-D5) -> 6 | J6: =D6-$D$2 -> 18 | K6: Store | L6: =H6/I6 -> 21.4 | M6: =SUM(H$2:H6) -> 465 | N6: 0 | P6: 0 | Q6: 0 | R6: Trinity to 100 East 10th Street | S6: =VLOOKUP(Table1[[#This Row],[Route]],'Dropdown Lists'!$M$2:$N$7,2,FALSE) -> 13.5
A7: =WEEKNUM(D7,1) -> 20 | B7: =WEEKNUM(C7,1) -> 33 | C7: =D7+92 -> 45153 | D7: 45061 | E7: =TEXT(D7,"dddd") -> Monday | F7: 100 East 10th Street | G7: 79.5 | H7: =G7-8 -> 71.5 | I7: =IF(D7-D6<0, 0, D7-D6) -> 3 | J7: =D7-$D$2 -> 21 | K7: Scheduled | L7: =H7/I7 -> 23.833333 | M7: =SUM(H$2:H7) -> 536.5 | N7: 0 | P7: 0 | Q7: 0 | R7: Trinity to 100 East 10th Street | S7: =VLOOKUP(Table1[[#This Row],[Route]],'Dropdown Lists'!$M$2:$N$7,2,FALSE) -> 13.5
A8: =WEEKNUM(D8,1) -> 20 | B8: =WEEKNUM(C8,1) -> 34 | C8: =D8+92 -> 45158 | D8: 45066 | E8: =TEXT(D8,"dddd") -> Saturday | F8: 100 East 10th Street | G8: 104.1 | H8: =G8-8 -> 96.1 | I8: =IF(D8-D7<0, 0, D8-D7) -> 5 | J8: =D8-$D$2 -> 26 | K8: Store | L8: =H8/I8 -> 19.22 | M8: =SUM(H$2:H8) -> 632.6 | N8: 0 | P8: 0 | Q8: 0 | R8: Home to 100 East 10th Street | S8: =VLOOKUP(Table1[[#This Row],[Route]],'Dropdown Lists'!$M$2:$N$7,2,FALSE) -> 11.4
A9: =WEEKNUM(D9,1) -> 21 | B9: =WEEKNUM(C9,1) -> 34 | C9: =D9+92 -> 45161 | D9: 45069 | E9: =TEXT(D9,"dddd") -> Tuesday | F9: 100 East 10th Street | G9: 165.2 | H9: =G9-8 -> 157.2 | I9: =IF(D9-D8<0, 0, D9-D8) -> 3 | J9: =D9-$D$2 -> 29 | K9: Store | L9: =H9/I9 -> 52.4 | M9: =SUM(H$2:H9) -> 789.8 | N9: 0 | P9: 0 | Q9: 0 | R9: Trinity to 100 East 10th Street | S9: =VLOOKUP(Table1[[#This Row],[Route]],'Dropdown Lists'!$M$2:$N$7,2,FALSE) -> 13.5
A10: =WEEKNUM(D10,1) -> 21 | B10: =WEEKNUM(C10,1) -> 34 | C10: =D10+92 -> 45164 | D10: 45072 | E10: =TEXT(D10,"dddd") -> Friday | F10: 100 East 10th Street | G10: 166.5 | H10: =G10-8 -> 158.5 | I10: =IF(D10-D9<0, 0, D10-D9) -> 3 | J10: =D10-$D$2 -> 32 | K10: Store | L10: =H10/I10 -> 52.833333 | M10: =SUM(H$2:H10) -> 948.3 | N10: 0 | P10: 0 | Q10: 0 | R10: Home to 100 East 10th Street | S10: =VLOOKUP(Table1[[#This Row],[Route]],'Dropdown Lists'!$M$2:$N$7,2,FALSE) -> 11.4
A11: =WEEKNUM(D11,1) -> 22 | B11: =WEEKNUM(C11,1) -> 35 | C11: =D11+92 -> 45169 | D11: 45077 | E11: =TEXT(D11,"dddd") -> Wednesday | F11: 100 East 10th Street | G11: 127.6 | H11: =G11-8 -> 119.6 | I11: =IF(D11-D10<0, 0, D11-D10) -> 5 | J11: =D11-$D$2 -> 37 | K11: Store | L11: =H11/I11 -> 23.92 | M11: =SUM(H$2:H11) -> 1067.9 | N11: 0 | P11: 0 | Q11: 0 | R11: Home to 100 East 10th Street | S11: =VLOOKUP(Table1[[#This Row],[Route]],'Dropdown Lists'!$M$2:$N$7,2,FALSE) -> 11.4
A12: =WEEKNUM(D12,1) -> 23 | B12: =WEEKNUM(C12,1) -> 36 | C12: =D12+92 -> 45177 | D12: 45085 | E12: =TEXT(D12,"dddd") -> Thursday | F12: 100 East 10th Street | G12: 160.8 | H12: =G12-8 -> 152.8 | I12: =IF(D12-D11<0, 0, D12-D11) -> 8 | J12: =D12-$D$2 -> 45 | K12: Store | L12: =H12/I12 -> 19.1 | M12: =SUM(H$2:H12) -> 1220.7 | N12: 0 | P12: 0 | Q12: 0 | R12: Home to 100 East 10th Street | S12: =VLOOKUP(Table1[[#This Row],[Route]],'Dropdown Lists'!$M$2:$N$7,2,FALSE) -> 11.4
A13: =WEEKNUM(D13,1) -> 24 | B13: =WEEKNUM(C13,1) -> 37 | C13: =D13+92 -> 45181 | D13: 45089 | E13: =TEXT(D13,"dddd") -> Monday | F13: 100 East 10th Street | G13: 141.5 | H13: =G13-8 -> 133.5 | I13: =IF(D13-D12<0, 0, D13-D12) -> 4 | J13: =D13-$D$2 -> 49 | K13: Store | L13: =H13/I13 -> 33.375 | M13: =SUM(H$2:H13) -> 1354.2 | N13: 0 | P13: 0 | Q13: 0 | R13: Home to 100 East 10th Street | S13: =VLOOKUP(Table1[[#This Row],[Route]],'Dropdown Lists'!$M$2:$N$7,2,FALSE) -> 11.4
A14: =WEEKNUM(D14,1) -> 24 | B14: =WEEKNUM(C14,1) -> 37 | C14: =D14+92 -> 45184 | D14: 45092 | E14: =TEXT(D14,"dddd") -> Thursday | F14: 100 East 10th Street | G14: 134.5 | H14: =G14-8 -> 126.5 | I14: =IF(D14-D13<0, 0, D14-D13) -> 3 | J14: =D14-$D$2 -> 52 | K14: Store | L14: =H14/I14 -> 42.166667 | M14: =SUM(H$2:H14) -> 1480.7 | N14: 0 | P14: 0 | Q14: 0 | R14: Home to 100 East 10th Street | S14: =VLOOKUP(Table1[[#This Row],[Route]],'Dropdown Lists'!$M$2:$N$7,2,FALSE) -> 11.4
... A47: =WEEKNUM(D47,1) -> 39 | B47: =WEEKNUM(C47,1) -> 52 | C47: =D47+92 -> 45289 | D47: 45197 | E47: =TEXT(D47,"dddd") -> Thursday | F47: 100 East 10th Street | G47: 200 | H47: =G47-8 -> 192 | I47: =IF(D47-D46<0, 0, D47-D46) -> 2 | J47: =D47-$D$2 -> 157 | K47: Store | L47: =H47/I47 -> 96 | M47: =SUM(H$2:H47) -> 6173.2 | N47: 0 | P47: 5 | Q47: 0 | R47: Trinity to 100 East 10th Street | S47: =VLOOKUP(Table1[[#This Row],[Route]],'Dropdown Lists'!$M$2:$N$7,2,FALSE) -> 13.5
A48: =WEEKNUM(D48,1) -> 39 | D48: 45199 | E48: =TEXT(D48,"dddd") -> Saturday | F48: 100 East 10th Street | G48: 195 | H48: =G48-8 -> 187 | I48: =IF(D48-D47<0, 0, D48-D47) -> 2 | J48: =D48-$D$2 -> 159 | K48: Scheduled | L48: =H48/I48 -> 93.5 | M48: =SUM(H$2:H48) -> 6360.2 | N48: 0 | P48: 2 | Q48: 0 | R48: Home to 100 East 10th Street | S48: =VLOOKUP(Table1[[#This Row],[Route]],'Dropdown Lists'!$M$2:$N$7,2,FALSE) -> 11.4
A49: =WEEKNUM(D49,1) -> 40 | D49: 45201 | E49: =TEXT(D49,"dddd") -> Monday | F49: 100 East 10th Street | G49: 81.5 | H49: =G49-8 -> 73.5 | I49: =IF(D49-D48<0, 0, D49-D48) -> 2 | J49: =D49-$D$2 -> 161 | K49: Scheduled | L49: =H49/I49 -> 36.75 | M49: =SUM(H$2:H49) -> 6433.7 | N49: 0 | P49: 8 | Q49: 0 | R49: Trinity to 100 East 10th Street | S49: =VLOOKUP(Table1[[#This Row],[Route]],'Dropdown Lists'!$M$2:$N$7,2,FALSE) -> 13.5
A50: =WEEKNUM(D50,1) -> 40 | D50: 45203 | E50: =TEXT(D50,"dddd") -> Wednesday | F50: 100 East 10th Street | G50: 127 | H50: =G50-8 -> 119 | I50: =IF(D50-D49<0, 0, D50-D49) -> 2 | J50: =D50-$D$2 -> 163 | K50: Scheduled | L50: =H50/I50 -> 59.5 | M50: =SUM(H$2:H50) -> 6552.7 | N50: 0 | P50: 8 | Q50: 0 | R50: Trinity to 100 East 10th Street | S50: =VLOOKUP(Table1[[#This Row],[Route]],'Dropdown Lists'!$M$2:$N$7,2,FALSE) -> 13.5
A51: =WEEKNUM(D51,1) -> 40 | D51: 45205 | E51: =TEXT(D51,"dddd") -> Friday | F51: 100 East 10th Street | G51: 190 | H51: =G51-8 -> 182 | I51: =IF(D51-D50<0, 0, D51-D50) -> 2 | J51: =D51-$D$2 -> 165 | K51: Scheduled | L51: =H51/I51 -> 91 | M51: =SUM(H$2:H51) -> 6734.7 | N51: 0 | P51: 8 | Q51: 0 | R51: Trinity to 100 East 10th Street | S51: =VLOOKUP(Table1[[#This Row],[Route]],'Dropdown Lists'!$M$2:$N$7,2,FALSE) -> 13.5
A52: =WEEKNUM(D52,1) -> 41 | D52: 45208 | E52: =TEXT(D52,"dddd") -> Monday | F52: 100 East 10th Street | G52: 120 | H52: =G52-8 -> 112 | I52: =IF(D52-D51<0, 0, D52-D51) -> 3 | J52: =D52-$D$2 -> 168 | K52: Scheduled | L52: =H52/I52 -> 37.333333 | M52: =SUM(H$2:H52) -> 6846.7 | N52: 0 | P52: 8 | Q52: 0 | R52: Trinity to 100 East 10th Street | S52: =VLOOKUP(Table1[[#This Row],[Route]],'Dropdown Lists'!$M$2:$N$7,2,FALSE) -> 13.5
A53: =WEEKNUM(D53,1) -> 41 | D53: 45210 | E53: =TEXT(D53,"dddd") -> Wednesday | F53: 100 East 10th Street | G53: 146.5 | H53: =G53-8 -> 138.5 | I53: =IF(D53-D52<0, 0, D53-D52) -> 2 | J53: =D53-$D$2 -> 170 | K53: Scheduled | L53: =H53/I53 -> 69.25 | M53: =SUM(H$2:H53) -> 6985.2 | N53: 0 | P53: 13.5 | Q53: 7.8 | R53: Trinity to 100 East 10th Street | S53: =VLOOKUP(Table1[[#This Row],[Route]],'Dropdown Lists'!$M$2:$N$7,2,FALSE) -> 13.5
A54: =WEEKNUM(D54,1) -> 41 | D54: 45212 | E54: =TEXT(D54,"dddd") -> Friday | F54: 100 East 10th Street | G54: 155.5 | H54: =G54-8 -> 147.5 | I54: =IF(D54-D53<0, 0, D54-D53) -> 2 | J54: =D54-$D$2 -> 172 | K54: Scheduled | L54: =H54/I54 -> 73.75 | M54: =SUM(H$2:H54) -> 7132.7 | N54: 0 | P54: =6.5+3+5.5 -> 15 | Q54: 10.5 | R54: Trinity to 100 East 10th Street | S54: =VLOOKUP(Table1[[#This Row],[Route]],'Dropdown Lists'!$M$2:$N$7,2,FALSE) -> 13.5
A55: =WEEKNUM(D55,1) -> 42 | D55: 45214 | E55: =TEXT(D55,"dddd") -> Sunday | F55: 100 East 10th Street | G55: 175 | H55: =G55-8 -> 167 | I55: =IF(D55-D54<0, 0, D55-D54) -> 2 | J55: =D55-$D$2 -> 174 | K55: Scheduled | L55: =H55/I55 -> 83.5 | M55: =SUM(H$2:H55) -> 7299.7 | N55: 0 | P55: 10 | Q55: 10 | R55: Home to 100 East 10th Street | S55: =VLOOKUP(Table1[[#This Row],[Route]],'Dropdown Lists'!$M$2:$N$7,2,FALSE) -> 11.4
A56: =WEEKNUM(D56,1) -> 42 | D56: 45216 | E56: =TEXT(D56,"dddd") -> Tuesday | F56: 100 East 10th Street | G56: 66 | H56: =G56-8 -> 58 | I56: =IF(D56-D55<0, 0, D56-D55) -> 2 | J56: =D56-$D$2 -> 176 | K56: Scheduled | L56: =H56/I56 -> 29 | M56: =SUM(H$2:H56) -> 7357.7 | N56: 0 | P56: 10 | Q56: 0 | R56: Trinity to 100 East 10th Street | S56: =VLOOKUP(Table1[[#This Row],[Route]],'Dropdown Lists'!$M$2:$N$7,2,FALSE) -> 13.5
A57: =WEEKNUM(D57,1) -> 42 | D57: 45218 | E57: =TEXT(D57,"dddd") -> Thursday | F57: 100 East 10th Street | G57: 104 | H57: =G57-8 -> 96 | I57: =IF(D57-D56<0, 0, D57-D56) -> 2 | J57: =D57-$D$2 -> 178 | K57: Scheduled | L57: =H57/I57 -> 48 | M57: =SUM(H$2:H57) -> 7453.7 | N57: 0 | P57: 20 | Q57: 8 | R57: Trinity to 100 East 10th Street | S57: =VLOOKUP(Table1[[#This Row],[Route]],'Dropdown Lists'!$M$2:$N$7,2,FALSE) -> 13.5
A58: =WEEKNUM(D58,1) -> 42 | D58: 45220 | E58: =TEXT(D58,"dddd") -> Saturday | F58: 100 East 10th Street | G58: 203 | H58: =G58-8 -> 195 | I58: =IF(D58-D57<0, 0, D58-D57) -> 2 | J58: =D58-$D$2 -> 180 | K58: Store | L58: =H58/I58 -> 97.5 | M58: =SUM(H$2:H58) -> 7648.7 | N58: 0 | P58: 8 | Q58: 5.5 | R58: Home to 100 East 10th Street | S58: =VLOOKUP(Table1[[#This Row],[Route]],'Dropdown Lists'!$M$2:$N$7,2,FALSE) -> 11.4
A59: =WEEKNUM(D59,1) -> 43 | D59: 45223 | E59: =TEXT(D59,"dddd") -> Tuesday | F59: 100 East 10th Street | G59: 215.5 | H59: =G59-8 -> 207.5 | I59: =IF(D59-D58<0, 0, D59-D58) -> 3 | J59: =D59-$D$2 -> 183 | K59: Scheduled | L59: =H59/I59 -> 69.166667 | M59: =SUM(H$2:H59) -> 7856.2 | N59: 0 | P59: 3.5 | Q59: 3.5 | R59: Trinity to 100 East 10th Street | S59: =VLOOKUP(Table1[[#This Row],[Route]],'Dropdown Lists'!$M$2:$N$7,2,FALSE) -> 13.5
A60: =WEEKNUM(D60,1) -> 43 | D60: 45225 | E60: =TEXT(D60,"dddd") -> Thursday | F60: 100 East 10th Street | G60: 98 | H60: =G60-8 -> 90 | I60: =IF(D60-D59<0, 0, D60-D59) -> 2 | J60: =D60-$D$2 -> 185 | K60: Scheduled | L60: =H60/I60 -> 45 | M60: =SUM(H$2:H60) -> 7946.2 | N60: 0 | P60: 18 | Q60: 23 | R60: Trinity to 100 East 10th Street | S60: =VLOOKUP(Table1[[#This Row],[Route]],'Dropdown Lists'!$M$2:$N$7,2,FALSE) -> 13.5
A61: =WEEKNUM(D61,1) -> 44 | D61: 45228 | E61: =TEXT(D61,"dddd") -> Sunday | F61: 100 East 10th Street | G61: 108 | H61: =G61-8 -> 100 | I61: =IF(D61-D60<0, 0, D61-D60) -> 3 | J61: =D61-$D$2 -> 188 | K61: Scheduled | L61: =H61/I61 -> 33.333333 | M61: =SUM(H$2:H61) -> 8046.2 | N61: 0 | P61: 0 | Q61: 0 | R61: Home to 100 East 10th Street | S61: =VLOOKUP(Table1[[#This Row],[Route]],'Dropdown Lists'!$M$2:$N$7,2,FALSE) -> 11.4
A62: =WEEKNUM(D62,1) -> 44 | D62: 45229 | E62: =TEXT(D62,"dddd") -> Monday | F62: 100 East 10th Street | G62: 194 | H62: =G62-8 -> 186 | I62: =IF(D62-D61<0, 0, D62-D61) -> 1 | J62: =D62-$D$2 -> 189 | K62: Scheduled | L62: =H62/I62 -> 186 | M62: =SUM(H$2:H62) -> 8232.2 | N62: 0 | P62: 15 | Q62: 0 | R62: Trinity to 100 East 10th Street | S62: =VLOOKUP(Table1[[#This Row],[Route]],'Dropdown Lists'!$M$2:$N$7,2,FALSE) -> 13.5
A63: =WEEKNUM(D63,1) -> 44 | D63: 45231 | E63: =TEXT(D63,"dddd") -> Wednesday | F63: 100 East 10th Street | G63: 153.5 | H63: =G63-8 -> 145.5 | I63: =IF(D63-D62<0, 0, D63-D62) -> 2 | J63: =D63-$D$2 -> 191 | K63: Scheduled | L63: =H63/I63 -> 72.75 | M63: =SUM(H$2:H63) -> 8377.7 | N63: 0 | P63: 0 | Q63: 0 | R63: Trinity to 100 East 10th Street | S63: =VLOOKUP(Table1[[#This Row],[Route]],'Dropdown Lists'!$M$2:$N$7,2,FALSE) -> 13.5
A64: =WEEKNUM(D64,1) -> 44 | D64: 45233 | E64: =TEXT(D64,"dddd") -> Friday | F64: 100 East 10th Street | G64: 181 | H64: =G64-8 -> 173 | I64: =IF(D64-D63<0, 0, D64-D63) -> 2 | J64: =D64-$D$2 -> 193 | K64: Scheduled | L64: =H64/I64 -> 86.5 | M64: =SUM(H$2:H64) -> 8550.7 | N64: 0 | P64: 4 | Q64: 19 | R64: Trinity to 100 East 10th Street | S64: =VLOOKUP(Table1[[#This Row],[Route]],'Dropdown Lists'!$M$2:$N$7,2,FALSE) -> 13.5
A65: =WEEKNUM(D65,1) -> 45 | D65: 45236 | E65: =TEXT(D65,"dddd") -> Monday | F65: 100 East 10th Street | G65: 171 | H65: =G65-8 -> 163 | I65: =IF(D65-D64<0, 0, D65-D64) -> 3 | J65: =D65-$D$2 -> 196 | K65: Scheduled | L65: =H65/I65 -> 54.333333 | M65: =SUM(H$2:H65) -> 8713.7 | N65: 0 | P65: 5 | Q65: 10.5 | R65: Trinity to 100 East 10th Street | S65: =VLOOKUP(Table1[[#This Row],[Route]],'Dropdown Lists'!$M$2:$N$7,2,FALSE) -> 13.5
A66: =WEEKNUM(D66,1) -> 45 | D66: 45238 | E66: =TEXT(D66,"dddd") -> Wednesday | F66: 100 East 10th Street | G66: 141.5 | H66: =G66-8 -> 133.5 | I66: =IF(D66-D65<0, 0, D66-D65) -> 2 | J66: =D66-$D$2 -> 198 | K66: Scheduled | L66: =H66/I66 -> 66.75 | M66: =SUM(H$2:H66) -> 8847.2 | N66: 0 | P66: 0 | Q66: 0 | R66: Trinity to 100 East 10th Street | S66: =VLOOKUP(Table1[[#This Row],[Route]],'Dropdown Lists'!$M$2:$N$7,2,FALSE) -> 13.5
A67: =WEEKNUM(D67,1) -> 45 | D67: 45240 | E67: =TEXT(D67,"dddd") -> Friday | F67: 100 East 10th Street | G67: 152 | H67: =G67-8 -> 144 | I67: =IF(D67-D66<0, 0, D67-D66) -> 2 | J67: =D67-$D$2 -> 200 | K67: Scheduled | L67: =H67/I67 -> 72 | M67: =SUM(H$2:H67) -> 8991.2 | N67: 0 | P67: 17.5 | Q67: 13 | R67: Trinity to 100 East 10th Street | S67: =VLOOKUP(Table1[[#This Row],[Route]],'Dropdown Lists'!$M$2:$N$7,2,FALSE) -> 13.5
A68: =WEEKNUM(D68,1) -> 46 | D68: 45242 | E68: =TEXT(D68,"dddd") -> Sunday | F68: 100 East 10th Street | G68: 75 | H68: =G68-8 -> 67 | I68: =IF(D68-D67<0, 0, D68-D67) -> 2 | J68: =D68-$D$2 -> 202 | K68: Scheduled | L68: =H68/I68 -> 33.5 | M68: =SUM(H$2:H68) -> 9058.2 | N68: 0 | P68: 1.5 | Q68: =18.5+1+8.5+3+16.5+5 -> 52.5 | R68: Home to 100 East 10th Street | S68: =VLOOKUP(Table1[[#This Row],[Route]],'Dropdown Lists'!$M$2:$N$7,2,FALSE) -> 11.4
A69: =WEEKNUM(D69,1) -> 47 | D69: 45250 | E69: =TEXT(D69,"dddd") -> Monday | F69: 100 East 10th Street | G69: =257+167+154 -> 578 | H69: =G69-8 -> 570 | I69: =IF(D69-D68<0, 0, D69-D68) -> 8 | J69: =D69-$D$2 -> 210 | K69: Scheduled | L69: =H69/I69 -> 71.25 | M69: =SUM(H$2:H69) -> 9628.2 | N69: 0 | P69: 32.5 | Q69: 0 | R69: Home to 100 East 10th Street | S69: =VLOOKUP(Table1[[#This Row],[Route]],'Dropdown Lists'!$M$2:$N$7,2,FALSE) -> 11.4
A70: =WEEKNUM(D70,1) -> 47 | D70: 45252 | E70: =TEXT(D70,"dddd") -> Wednesday | F70: 100 East 10th Street | G70: 160 | H70: =G70-8 -> 152 | I70: =IF(D70-D69<0, 0, D70-D69) -> 2 | J70: =D70-$D$2 -> 212 | K70: Scheduled | L70: =H70/I70 -> 76 | M70: =SUM(H$2:H70) -> 9780.2 | N70: 0 | P70: 10 | Q70: 3 | R70: Home to 100 East 10th Street | S70: =VLOOKUP(Table1[[#This Row],[Route]],'Dropdown Lists'!$M$2:$N$7,2,FALSE) -> 11.4
A71: =WEEKNUM(D71,1) -> 48 | D71: 45256 | E71: =TEXT(D71,"dddd") -> Sunday | F71: 100 East 10th Street | G71: 157 | H71: =G71-8 -> 149 | I71: =IF(D71-D70<0, 0, D71-D70) -> 4 | J71: =D71-$D$2 -> 216 | K71: Scheduled | L71: =H71/I71 -> 37.25 | M71: =SUM(H$2:H71) -> 9929.2 | N71: 0 | P71: 2 | Q71: =23+23.5+31.5 -> 78 | R71: Home to 100 East 10th Street | S71: =VLOOKUP(Table1[[#This Row],[Route]],'Dropdown Lists'!$M$2:$N$7,2,FALSE) -> 11.4
A72: =WEEKNUM(D72,1) -> 48 | D72: 45258 | E72: =TEXT(D72,"dddd") -> Tuesday | F72: 100 East 10th Street | G72: 107.5 | H72: =G72-8 -> 99.5 | I72: =IF(D72-D71<0, 0, D72-D71) -> 2 | J72: =D72-$D$2 -> 218 | K72: Scheduled | L72: =H72/I72 -> 49.75 | M72: =SUM(H$2:H72) -> 10028.7 | N72: 0 | P72: =21+6 -> 27 | Q72: 32 | R72: Home to 100 East 10th Street | S72: =VLOOKUP(Table1[[#This Row],[Route]],'Dropdown Lists'!$M$2:$N$7,2,FALSE) -> 11.4
...

Sheet Coffee Grounds Stats
B3: Stats since Apr. 24, 2023 | H3: Top 10 Collections
B4: Values | H4: Date | I4: Total Collected lbs | J4: Avg lbs per day since prev collection | K4: # of Days between collections | N4: Collections by Month
B5: Total Coffee Grounds Collected | C5: 58635.443 | D5: lbs | G5: 1 | H5: 46111 | I5: 587.08 | J5: 83.868571 | K5: 7 | N5: Net lbs
B6: Number of Collections | C6: 254 | G6: 2 | H6: 45250 | I6: 570 | J6: 71.25 | K6: 8 | N6: 58635.443
B7: Avg # of Days between collections | C7: 5.3320158 | D7: days | G7: 3 | H7: 45706 | I7: 556.22 | J7: 50.565455 | K7: 11
B8: Avg lbs per collection | C8: 230.8482 | D8: lbs | G8: 4 | H8: 45717 | I8: 525.88 | J8: 47.807273 | K8: 11
G9: 5 | H9: 46090 | I9: 519.48 | J9: 57.72 | K9: 9
B10: Avg lbs per day | C10: =C5/MAX('Collection DB'!J$1:J$298) -> 49.23211 | D10: lbs | G10: 6 | H10: 45608 | I10: 518 | J10: 8.09375 | K10: 64
C11: =C10*7 -> 344.62477 | G11: 7 | H11: 45736 | I11: 504.78 | J11: 56.086667 | K11: 9
B12: Collections by Day of the Week | G12: 8 | H12: 46146 | I12: 503.46 | J12: 71.922857 | K12: 7
B13: Row Labels | C13: Net lbs | D13: # of Collections | E13: Avg per pickup | G13: 9 | H13: 46062 | I13: 500.86 | J13: 71.551429 | K13: 7
A14: 1 | B14: Monday | C14: 26027.9 | D14: 91 | E14: 286.02088 | G14: 10 | H14: 45523 | I14: 499 | J14: 83.166667 | K14: 6
A15: 2 | B15: Wednesday | C15: 7167.1925 | D15: 32 | E15: 223.97477
A16: 3 | B16: Tuesday | C16: 6726.26 | D16: 34 | E16: 197.83118
A17: 4 | B17: Thursday | C17: 5674.96 | D17: 31 | E17: 183.06323
A18: 5 | B18: Friday | C18: 5308.29 | D18: 26 | E18: 204.165
A19: 6 | B19: Saturday | C19: 4023.76 | D19: 19 | E19: 211.77684
A20: 7 | B20: Sunday | C20: 3707.08 | D20: 21 | E20: 176.52762
B21: Grand Total | C21: 58635.443 | D21: 254 | E21: 230.8482
B24: Row Labels | C24: Sum of Net lbs
B25: 1 | C25: 557.14
B26: 2 | C26: 1414.44
B27: 3 | C27: 541.55
B28: 4 | C28: 2158.58
B29: 5 | C29: 1621.2
B30: 6 | C30: 1939.98
B31: 7 | C31: 1765.84
B32: 8 | C32: 2040.64
B33: 9 | C33: 2880.74
B34: 10 | C34: 976.11
B35: 11 | C35: 1763.7
B36: 12 | C36: 1713.04
... B76: 52 | C76: 1019.66
B77: (blank)
B78: 53 | C78: 197.22
B79: Grand Total | C79: 58635.442

Sheet Sheet2
K1: 52000 | M1: 65 | N1: 260
B2: Avg lbs per week | C2: 375.01231 | K2: 1600 | M2: 3380 | N2: 3900
B3: Max | C3: 765.6125 | D3: Wk 24 2024 | K3: 19200
B4: Min | C4: 67 | D4: Wk 46 2023
B5: St Dev | C5: 159.70002

Sheet Master Gardener
C2: Master Gardender SCG Deposits
C3: Date | D3: Spent Coffee Grounds (lbs)
C4: Row Labels | D4: Sum of Master Gardener
C5: 45040 | D5: 0
C6: 45043 | D6: 0
C7: 45050 | D7: 0
C8: 45052 | D8: 0
C9: 45058 | D9: 0
C10: 45061 | D10: 0
C11: 45066 | D11: 0
C12: 45069 | D12: 0
C13: 45072 | D13: 0
C14: 45077 | D14: 0
C15: 45085 | D15: 0
C16: 45089 | D16: 0
... C133: 45442 | D133: 321.75
C134: (blank)
C135: 45445 | D135: 0
C136: 45449 | D136: 0
C137: 45458 | D137: 0
C138: 45455 | D138: 329.8125
C139: 45461 | D139: 0
C140: 45473 | D140: 0
C141: 45478 | D141: 0
C142: 45490 | D142: 0
C143: 45495 | D143: 0
C144: 45468 | D144: 0
C145: 45499 | D145: 0
C146: 45506 | D146: 0
... C210: 46048 | D210: 0
C211: 1/26/2026 | D211: 0
C212: 46055 | D212: 0
C213: 46057 | D213: 0
C214: 46062 | D214: 0
C215: 46069 | D215: 0
C216: 46076 | D216: 0
C217: 46081 | D217: 0
C218: 46083 | D218: 0
C219: 46090 | D219: 0
C220: 46097 | D220: 182.34
...

Sheet Sheet1
M1: Date | N1: SCG mass lbs | O1: Net lbs
M2: 45250 | N2: =257+167+154 -> 578 | O2: =N2-8 -> 570
A3: Row Labels | B3: Net lbs | F3: Row Labels | G3: Average of Net lbs | H3: StdDev of Net lbs | I3: Max of Net lbs | J3: Min of Net lbs | M3: 45458 | N3: =126.8+191+134 -> 451.8 | O3: =N3-8 -> 443.8
A4: 1 | B4: 557.14 | F4: (blank) | M4: 45490 | N4: =83.58+179.58+186.5 -> 449.66 | O4: =N4-8 -> 441.66
A5: 2 | B5: 1414.44 | F5: 1 | G5: 557.14 | H5: #DIV/0! | I5: 557.14 | J5: 557.14 | M5: 45449 | N5: =115.82+161.68+170.48 -> 447.98 | O5: =N5-8 -> 439.98
A6: 3 | B6: 541.55 | F6: 2 | G6: 1414.44 | H6: #DIV/0! | I6: 1414.44 | J6: 1414.44 | M6: 45473 | N6: =112.04+138.84+147.76 -> 398.64 | O6: =N6-8 -> 390.64
A7: 4 | B7: 2158.58 | F7: 3 | G7: 541.55 | H7: #DIV/0! | I7: 541.55 | J7: 541.55 | M7: 45301 | N7: =184+198 -> 382 | O7: =N7-8 -> 374
A8: 5 | B8: 1621.2 | F8: 4 | G8: 2158.58 | H8: #DIV/0! | I8: 2158.58 | J8: 2158.58 | M8: 45411 | N8: =199+180 -> 379 | O8: =N8-8 -> 371
A9: 6 | B9: 1939.98 | F9: 5 | G9: 1621.2 | H9: #DIV/0! | I9: 1621.2 | J9: 1621.2 | M9: 45390 | N9: 377 | O9: =N9-8 -> 369
A10: 7 | B10: 1765.84 | F10: 6 | G10: 1939.98 | H10: #DIV/0! | I10: 1939.98 | J10: 1939.98 | M10: 45432 | N10: =169.9+206.15 -> 376.05 | O10: =N10-8 -> 368.05
A11: 8 | B11: 2040.64 | F11: 7 | G11: 1765.84 | H11: #DIV/0! | I11: 1765.84 | J11: 1765.84 | M11: 45442 | N11: =198+175 -> 373 | O11: =N11-8 -> 365
A12: 9 | B12: 2880.74 | F12: 8 | G12: 2040.64 | H12: #DIV/0! | I12: 2040.64 | J12: 2040.64 | M12: 45478 | N12: =195.48+177.08 -> 372.56 | O12: =N12-8 -> 364.56
A13: 10 | B13: 976.11 | F13: 9 | G13: 2880.74 | H13: #DIV/0! | I13: 2880.74 | J13: 2880.74 | M13: 45455 | N13: =155.375+174.4375 -> 329.8125 | O13: =N13-8 -> 321.8125
A14: 11 | B14: 1763.7 | F14: 10 | G14: 976.11 | H14: #DIV/0! | I14: 976.11 | J14: 976.11 | M14: 45418 | N14: =190.14+127.2 -> 317.34 | O14: =N14-8 -> 309.34
A15: 12 | B15: 1713.04 | F15: 11 | G15: 1763.7 | H15: #DIV/0! | I15: 1763.7 | J15: 1763.7 | M15: 45355 | N15: =156*2 -> 312 | O15: =N15-8 -> 304
A16: 13 | B16: 1831.16 | F16: 12 | G16: 1713.04 | H16: #DIV/0! | I16: 1713.04 | J16: 1713.04 | M16: 45362 | N16: =156*2 -> 312 | O16: =N16-8 -> 304
A17: 14 | B17: 1874.04 | F17: 13 | G17: 1831.16 | H17: #DIV/0! | I17: 1831.16 | J17: 1831.16 | M17: 45427 | N17: =149.5+159.04 -> 308.54 | O17: =N17-8 -> 300.54
A18: 15 | B18: 2178.61 | F18: 14 | G18: 1874.04 | H18: #DIV/0! | I18: 1874.04 | J18: 1874.04 | M18: 45276 | N18: =111.5+192 -> 303.5 | O18: =N18-8 -> 295.5
A19: 16 | B19: 1563.14 | F19: 15 | G19: 2178.61 | H19: #DIV/0! | I19: 2178.61 | J19: 2178.61 | M19: 45272 | N19: =150+109.5 -> 259.5 | O19: =N19-8 -> 251.5
A20: 17 | B20: 2107.88 | F20: 16 | G20: 1563.14 | H20: #DIV/0! | I20: 1563.14 | J20: 1563.14 | M20: 45223 | N20: 215.5 | O20: =N20-8 -> 207.5
A21: 18 | B21: 1852.32 | F21: 17 | G21: 2107.88 | H21: #DIV/0! | I21: 2107.88 | J21: 2107.88 | M21: 45383 | N21: 215 | O21: =N21-8 -> 207
A22: 19 | B22: 1822.84 | F22: 18 | G22: 1852.32 | H22: #DIV/0! | I22: 1852.32 | J22: 1852.32 | M22: 45312 | N22: 212 | O22: =N22-8 -> 204
A23: 20 | B23: 859.54 | F23: 19 | G23: 1822.84 | H23: #DIV/0! | I23: 1822.84 | J23: 1822.84 | M23: 45434 | N23: 207 | O23: =N23-8 -> 199
A24: 21 | B24: 1169.07 | F24: 20 | G24: 859.54 | H24: #DIV/0! | I24: 859.54 | J24: 859.54 | M24: 45193 | N24: 206 | O24: =N24-8 -> 198
A25: 22 | B25: 849.34 | F25: 21 | G25: 1169.07 | H25: #DIV/0! | I25: 1169.07 | J25: 1169.07 | M25: 45220 | N25: 203 | O25: =N25-8 -> 195
A26: 23 | B26: 973.73 | F26: 22 | G26: 849.34 | H26: #DIV/0! | I26: 849.34 | J26: 849.34 | M26: 45197 | N26: 200 | O26: =N26-8 -> 192
A27: 24 | B27: 1311.7325 | F27: 23 | G27: 973.73 | H27: #DIV/0! | I27: 973.73 | J27: 973.73 | M27: 45368 | N27: 200 | O27: =N27-8 -> 192
A28: 25 | B28: 685.68 | F28: 24 | G28: 1311.7325 | H28: #DIV/0! | I28: 1311.7325 | J28: 1311.7325 | M28: 45386 | N28: 200 | O28: =N28-8 -> 192
A29: 26 | B29: 637.92 | F29: 25 | G29: 685.68 | H29: #DIV/0! | I29: 685.68 | J29: 685.68 | M29: 45396 | N29: 200 | O29: =N29-8 -> 192
A30: 27 | B30: 1151.62 | F30: 26 | G30: 637.92 | H30: #DIV/0! | I30: 637.92 | J30: 637.92 | M30: 45406 | N30: 196 | O30: =N30-8 -> 188
A31: 28 | B31: 146 | F31: 27 | G31: 1151.62 | H31: #DIV/0! | I31: 1151.62 | J31: 1151.62 | M31: 45199 | N31: 195 | O31: =N31-8 -> 187
... A56: 53 | B56: 197.22 | F56: 52 | G56: 1019.66 | H56: #DIV/0! | I56: 1019.66 | J56: 1019.66 | M56: 45236 | N56: 171 | O56: =N56-8 -> 163
A57: Grand Total | B57: 58635.442 | F57: 53 | G57: 197.22 | H57: #DIV/0! | I57: 197.22 | J57: 197.22 | M57: 45178 | N57: 170.5 | O57: =N57-8 -> 162.5
F58: Grand Total | G58: 58635.442 | H58: #DIV/0! | I58: 58635.442 | J58: 58635.442 | M58: 45172 | N58: 170 | O58: =N58-8 -> 162
F59: Grand Total | G59: 2171.6831 | H59: 7852.9214 | I59: 58635.442 | J59: 146 | M59: 45268 | N59: 168 | O59: =N59-8 -> 160
M60: 45072 | N60: 166.5 | O60: =N60-8 -> 158.5
M61: 45191 | N61: 166 | O61: =N61-8 -> 158
M62: 45069 | N62: 165.2 | O62: =N62-8 -> 157.2
M63: 45338 | N63: 165 | O63: =N63-8 -> 157
M64: 45351 | N64: 165 | O64: =N64-8 -> 157
...

Sheet Calendar Scaffold
A1: Calendar Date
A2: 45017
A3: 45018
A4: 45019
A5: 45020
A6: 45021
A7: 45022
A8: 45023
A9: 45024
A10: 45025
A11: 45026
A12: 45027
A13: 45028
... A1800: 46815

Sheet Dropdown Lists
C1: Store List | D1: Lattitude | E1: Longitude | F1: Roundtrip distance (mi) | H1: Container List | I1: Container weight | K1: Who initiated pickup? | M1: Route | N1: Miles Driven (Roundtrip)
A2: =36000*2000 -> 72000000 | C2: 100 East 10th Street | D2: 35.605607 | E2: -77.373698 | F2: =5.7*2 -> 11.4 | H2: Hyper Tough Black | I2: 8 | K2: Me | M2: Home to 100 East 10th Street | N2: =5.7*2 -> 11.4
A3: =A2*12 -> 864000000 | C3: Greenville Blvd & Red Banks Rd | D3: 35.582406 | E3: -77.373526 | H3: Mike's | I3: 7 | K3: Store | M3: Trinity to 100 East 10th Street | N3: 13.5
C4: Stanton Sq & Arlington Dr | D4: 35.605979 | E4: -77.41378 | K4: Scheduled | M4: Trinity 3 Store Loop | N4: 19.5
C5: E. Fire Tower Rd & E. Arlingto | D5: 35.567507 | E5: -77.349322 | M5: Home to Red Banks | N5: 7.5
C6: Winterville | D6: 35.551995 | E6: -77.405799 | M6: Red Banks to 10th Street | N6: 1.9
C7: Fleet Feet Greenville | M7: 10th St to Stanton to Home | N7: 13.7
M8: Home to Stanton | N8: 7.5
